<mujoco model="finger">
  <compiler angle="radian"/>

  <option timestep="0.0075" impratio="10" iterations="1" ls_iterations="4">
    <flag eulerdamp="disable"/>
  </option>

  <visual>
    <quality shadowsize="2048"/>
    <headlight ambient="0.4 0.4 0.4" diffuse="0.8 0.8 0.8" specular="0.1 0.1 0.1"/>
  </visual>

  <default>
    <geom solimp="0 0.99 0.1"/>
    <general ctrllimited="true" ctrlrange="-1 1"/>
    <default class="finger">
      <site size="0.025 0.03 0.025" group="3" type="ellipsoid" rgba="0.5 0.5 0.5 0.3"/>
    </default>
  </default>

  <custom>
    <numeric name="max_contact_points" size="1" data="15"/>
    <numeric name="max_geom_pairs" size="1" data="15"/>
  </custom>

  <asset>
    <texture type="skybox" name="skybox" builtin="gradient" mark="random" rgb1="0.4 0.6 0.8" rgb2="0 0 0" markrgb="1 1 1" width="800" height="4800"/>
    <texture type="2d" name="grid" builtin="checker" mark="edge" rgb1="0.1 0.2 0.3" rgb2="0.2 0.3 0.4" markrgb="0.2 0.3 0.4" width="300" height="300"/>
    <material name="grid" texture="grid" texuniform="true" reflectance="0.2"/>
    <material name="self" rgba="0.7 0.5 0.3 1"/>
    <material name="self_default" rgba="0.7 0.5 0.3 1"/>
    <material name="self_highlight" rgba="0 0.5 0.3 1"/>
    <material name="effector" rgba="0.7 0.4 0.2 1"/>
    <material name="effector_default" rgba="0.7 0.4 0.2 1"/>
    <material name="effector_highlight" rgba="0 0.5 0.3 1"/>
    <material name="decoration" rgba="0.3 0.5 0.7 1"/>
    <material name="eye" rgba="0 0.2 1 1"/>
    <material name="target" rgba="0.6 0.3 0.3 1"/>
    <material name="target_default" rgba="0.6 0.3 0.3 1"/>
    <material name="target_highlight" rgba="0.6 0.3 0.3 0.4"/>
  </asset>

  <worldbody>
    <geom name="ground" size="0.6 0.2 10" pos="0 0 -0.6" type="plane" material="grid"/>
    <camera name="cam0" pos="0 -1 0.8" quat="0.850651 0.525731 0 0"/>
    <camera name="cam1" pos="0 -1 0.4" quat="0.707107 0.707107 0 0"/>
    <light name="light" pos="0 0 2" dir="0 0 -1" directional="true" diffuse="0.6 0.6 0.6"/>
    <body name="proximal" childclass="finger" pos="0 0 -0.01">
      <joint name="proximal" pos="0 0 0" axis="0 -1 0" ref="-1.5708" limited="false" range="-150 -80" damping="0.05"/>
      <geom name="proximal" size="0.03 0.085" pos="0 0 -0.085" type="capsule" material="self"/>
      <body name="distal" pos="0 0 -0.24">
        <joint name="distal" pos="0 0 0" axis="0 -1 0" limited="false" range="-50 50" damping="0.05"/>
        <geom name="distal" size="0.028 0.08" pos="0 0 -0.08" type="capsule" material="self"/>
      </body>
    </body>
    <body name="spinner" pos="0 0 -0.4">
      <joint name="hinge" pos="0 0 0" axis="0 -1 0" limited="false" range="-50 50" damping="0.35" frictionloss="0.01"/>
      <geom name="cap1" size="0.04 0.09" type="capsule" material="self"/>
    </body>
  </worldbody>

  <actuator>
    <general name="proximal" joint="proximal" gear="3 0 0 0 0 0"/>
    <general name="distal" joint="distal" gear="1.5 0 0 0 0 0"/>
  </actuator>
</mujoco>
