<mujoco model="cartpole">
  <compiler angle="radian"/>

  <option timestep="0.01" integrator="RK4">
    <flag contact="disable"/>
  </option>

  <visual>
    <quality shadowsize="2048"/>
    <headlight ambient="0.4 0.4 0.4" diffuse="0.8 0.8 0.8" specular="0.1 0.1 0.1"/>
  </visual>

  <asset>
    <texture type="skybox" name="skybox" builtin="gradient" mark="random" rgb1="0.4 0.6 0.8" rgb2="0 0 0" markrgb="1 1 1" width="800" height="4800"/>
    <texture type="2d" name="grid" builtin="checker" mark="edge" rgb1="0.1 0.2 0.3" rgb2="0.2 0.3 0.4" markrgb="0.2 0.3 0.4" width="300" height="300"/>
    <material name="grid" texture="grid" texuniform="true" reflectance="0.2"/>
    <material name="self" rgba="0.7 0.5 0.3 1"/>
    <material name="self_default" rgba="0.7 0.5 0.3 1"/>
    <material name="self_highlight" rgba="0 0.5 0.3 1"/>
    <material name="effector" rgba="0.7 0.4 0.2 1"/>
    <material name="effector_default" rgba="0.7 0.4 0.2 1"/>
    <material name="effector_highlight" rgba="0 0.5 0.3 1"/>
    <material name="decoration" rgba="0.3 0.5 0.7 1"/>
    <material name="eye" rgba="0 0.2 1 1"/>
    <material name="target" rgba="0.6 0.3 0.3 1"/>
    <material name="target_default" rgba="0.6 0.3 0.3 1"/>
    <material name="target_highlight" rgba="0.6 0.3 0.3 0.4"/>
  </asset>

  <worldbody>
    <geom name="floor" size="4 4 0.2" pos="0 0 -0.05" type="plane" material="grid"/>
    <geom name="rail1" size="0.02 4" pos="0 0.07 1" quat="0.707107 0 0.707107 0" type="capsule" material="decoration"/>
    <geom name="rail2" size="0.02 4" pos="0 -0.07 1" quat="0.707107 0 0.707107 0" type="capsule" material="decoration"/>
    <camera name="fixed" pos="0 -8 1" quat="0.707107 0.707107 0 0"/>
    <camera name="lookatcart" target="cart" pos="0 -2 2" mode="targetbody"/>
    <light name="light" pos="0 0 6" dir="0 0 -1"/>
    <body name="cart" pos="0 0 1">
      <joint name="slider" pos="0 0 0" axis="1 0 0" type="slide" solreflimit="0.08" limited="false" range="-1.8 1.8" damping="0.0005"/>
      <geom name="cart" size="0.2 0.15 0.1" type="box" mass="1" material="self"/>
    </body>
  </worldbody>

  <actuator>
    <general name="slide" joint="slider" ctrllimited="true" ctrlrange="-1 1" gear="10 0 0 0 0 0"/>
  </actuator>
</mujoco>
