<mujoco model="finger">

    <visual>
        <headlight ambient=".4 .4 .4" diffuse=".8 .8 .8" specular="0.1 0.1 0.1"/>
        <map znear=".01"/>
        <quality shadowsize="2048"/>
    </visual>

    <asset>
        <texture name="skybox" type="skybox" builtin="gradient" rgb1=".4 .6 .8" rgb2="0 0 0"
                 width="800" height="800" mark="random" markrgb="1 1 1"/>
    </asset>

    <asset>
        <texture name="grid" type="2d" builtin="checker" rgb1=".1 .2 .3" rgb2=".2 .3 .4" width="300" height="300" mark="edge" markrgb=".2 .3 .4"/>
        <material name="grid" texture="grid" texrepeat="1 1" texuniform="true" reflectance=".2"/>
        <material name="self" rgba=".7 .5 .3 1"/>
        <material name="self_default" rgba=".7 .5 .3 1"/>
        <material name="self_highlight" rgba="0 .5 .3 1"/>
        <material name="effector" rgba=".7 .4 .2 1"/>
        <material name="effector_default" rgba=".7 .4 .2 1"/>
        <material name="effector_highlight" rgba="0 .5 .3 1"/>
        <material name="decoration" rgba=".3 .5 .7 1"/>
        <material name="eye" rgba="0 .2 1 1"/>
        <material name="target" rgba=".6 .3 .3 1"/>
        <material name="target_default" rgba=".6 .3 .3 1"/>
        <material name="target_highlight" rgba=".6 .3 .3 .4"/>
    </asset>

<!--   important mjx options  -->
  <option timestep="0.0075" impratio="10" iterations="100" ls_iterations="4">
    <flag eulerdamp="disable"/>
  </option>

<!--  reduce contact computation for mjx -->
 <custom>
    <numeric data="15" name="max_contact_points"/>
    <numeric data="15" name="max_geom_pairs"/>
  </custom>

    <default>
        <geom solimp="0 0.99 0.1" solref="0.02 1"/>
        <joint type="hinge" axis="0 -1 0"/>
        <motor ctrllimited="true" ctrlrange="-1 1"/>
        <!-- <default class="finger">
            <site type="ellipsoid" size=".025 .03 .025" rgba=".5 .5 .5 .3" group="3"/>
        </default> -->
    </default>
 
    <worldbody>
        <light name="light" directional="true" diffuse=".6 .6 .6" pos="0 0 2" specular=".3 .3 .3"/>
        <geom name="ground" type="plane" pos="0 0 -0.6" size=".6 .2 10" material="grid"/>
        <camera name="cam0" pos="0 -1 .8" xyaxes="1 0 0 0 1 2"/>
        <camera name="cam1" pos="0 -1 .4" xyaxes="1 0 0 0 0 1" />

        <body name="proximal" pos="-.2 0 -0.01" >
            <geom name="proximal_decoration" type="cylinder" fromto="0 -.033 0 0 .033 0" size=".034" material="decoration" />
            <joint name="proximal" range="-150 -80" ref="-90" damping="0.05" limited="false" />
            <geom name="proximal" type="capsule" material="self" size=".03" fromto="0 0 0 0 0 -.17"/>
            <body name="distal" pos="0 0 -.18" >
                <joint name="distal" range="-50 50" damping="0.05" limited="false"/>
                <geom name="distal" type="capsule" size=".028" material="self" fromto="0 0 0 0 0 -.16"/>
                <geom name="fingertip" type="capsule" size=".03" material="effector" fromto="0 0 -.13 0 0 -.161"/>
                <site name="fingertip_site" type="sphere" pos="0 0 -0.161"  size="0.035" rgba="1. .97 0. 0.15"/>  
            </body>
        </body>

        <body name="spinner" pos="-.2 0 -.4">
            <joint name="hinge" range="-50 50" frictionloss=".01" damping=".35" limited="false"/>
            <geom name="cap1" type="capsule" size=".04 .09" material="self" pos=".02 0 0" />
            <geom name="cap2" type="capsule" size=".04 .09" material="self" pos="-.02 0 0"/>
            <!-- <site name="capsule_site" type="capsule" size=".065 .08" material="self" pos="0 0 0"  rgba=".3 .5 .7 0.25"/>--> 
            <site name="capsule_site" type="sphere" size="0.06" material="self" pos="0 0 0.1"  rgba=".3 .5 .7 0.25"/> 
            <geom name="spinner_decoration" type="cylinder" fromto="0 -.045 0 0 .045 0" size=".02" material="decoration"/>
            <geom name="target" pos="0. 0. 0.12" type="sphere" size="0.02" rgba=".3 .5 .7 0.25" contype="0" conaffinity="0"/>
            <site name="target_site" type="sphere" pos="0 0 0.12"  size=".015" rgba="1. .97 0. 0.8"/>    
        </body>

        <body mocap="true" name="target" pos="-.2 0 -.4" quat="0. 0.707107 0. 0.707107">
            <!-- A joint for tracking angular displacement -->
            <geom name="target_decoration" pos="0. 0. 0.12" type="sphere" size="0.02" rgba="0.961 0.294 0.145 0.25" contype="0" conaffinity="0"/>
        </body>


    </worldbody>


    <sensor>
        <touch name="touch_sphere" site="capsule_site" cutoff="1."/>
        <framepos name="pos_fingertip" objtype="site" objname="fingertip_site" reftype="world" refname="world"/>
        <framepos name="pos_spinner" objtype="site" objname="target_site" reftype="world" refname="world"/>
    </sensor>

    <actuator>
        <motor name="proximal" joint="proximal" gear="3"/>
        <motor name="distal" joint="distal" gear="1.5"/>
    </actuator>
</mujoco>