<mujoco model="planar point mass">
    <visual>
        <quality shadowsize="2048" />
        <headlight ambient="0.4 0.4 0.4" diffuse="0.8 0.8 0.8" specular="0.1 0.1 0.1" />
    </visual>

  <option impratio="10" iterations="1" ls_iterations="4" timestep="0.01">
    <flag eulerdamp="disable"/>
  </option>

  <custom>
    <numeric data="15" name="max_contact_points"/>
    <numeric data="15" name="max_geom_pairs"/>
  </custom>

    <asset>
        <texture type="skybox" name="skybox" builtin="gradient" mark="random" rgb1="0.4 0.6 0.8" rgb2="0 0 0" markrgb="1 1 1" width="800" height="4800" />
        <texture type="2d" name="grid" builtin="checker" mark="edge" rgb1="0.1 0.2 0.3" rgb2="0.2 0.3 0.4" markrgb="0.2 0.3 0.4" width="300" height="300" />
        <material name="grid" texture="grid" texuniform="true" reflectance="0.2" />
        <material name="self" rgba="0.7 0.5 0.3 1" />
        <material name="self_default" rgba="0.7 0.5 0.3 1" />
        <material name="self_highlight" rgba="0 0.5 0.3 1" />
        <material name="effector" rgba="0.7 0.4 0.2 1" />
        <material name="effector_default" rgba="0.7 0.4 0.2 1" />
        <material name="effector_highlight" rgba="0 0.5 0.3 1" />
        <material name="decoration" rgba="0.3 0.5 0.7 1" />
        <material name="eye" rgba="0 0.2 1 1" />
        <material name="target" rgba="0.6 0.3 0.3 1" />
        <material name="target_default" rgba="0.6 0.3 0.3 1" />
        <material name="target_highlight" rgba="0.6 0.3 0.3 0.4" />
    </asset>

    <worldbody>
        <camera name="fixed" pos="0 0 0.75" />
        <light name="light" pos="0 0 1" dir="0 0 -1" />


        <body name ="finger" pos="0.2 0.15 0.035" quat="0.707107 0.707107 0 0">
            <joint name="proximal" range="-150 -80" axis="0 -1 0" ref="-90" damping="0.05" limited="false" />
            <geom name="proximal" type="capsule" material="self" size=".03" fromto="0 0 0 0 0 -.17" contype="1" conaffinity="2"/>
            <body name="distal" pos="0 0 -.23">
                <joint name="distal" range="-50 50" axis="0 -1 0" damping="0.05" limited="false"/>
                <geom name="distal" type="capsule" size=".028" material="self" fromto="0 0 0 0 0 -.16" contype="1" conaffinity="2"/>
                <body name="distal2" pos="0 0 -.22">
                    <joint name="distal2" range="-50 50" axis="0 -1 0" damping="0.05" limited="false"/>
                    <geom name="distal2" type="capsule" size=".028" material="self" fromto="0 0 0 0 0 -.16" contype="1" conaffinity="2"/>
                </body>
            </body>
        </body>

        <body name="object" pos="0.0 0.0 0.035">
            <camera name="cam0" pos="0 -0.3 0.3" xyaxes="1 0 0 0 0.7 0.7"/>
            <joint name="root_x" type="slide"  pos="0 0 0" axis="1 0 0" damping="3" frictionloss=".01"/>
            <joint name="root_y" type="slide"  pos="0 0 0" axis="0 1 0" damping="3" frictionloss=".01"/>
            <geom name="pointmass" type="sphere" size=".042" material="self" mass=".6" condim="3"  group="2" solimp="0.0 0.95 0.1 0.5 2"
 solref="0.02 1.0"/>
        </body>

        <geom name="target" pos="0.25 -0.25 0.022" material="target" type="sphere" rgba="0.5 1 0 0.25"  size=".045" contype="0" conaffinity="0"/>
    </worldbody>

    <actuator>
        <general name="proximal" joint="proximal" gear="0.45 0 0 0 0 0"/>
        <general name="distal" joint="distal" gear="0.325 0 0 0 0 0"/>
        <general name="distal2" joint="distal2" gear="0.325 0 0 0 0 0"/>
    </actuator>
</mujoco>
