<mujoco model="planar point mass">
    <visual>
        <quality shadowsize="2048" />
        <headlight ambient="0.4 0.4 0.4" diffuse="0.8 0.8 0.8" specular="0.1 0.1 0.1" />
    </visual>

  <!--  Time step is very important any number above 0.008 leads to unstable results original time step is 0.0001 -->
  <option impratio="10" iterations="1" ls_iterations="4" timestep="0.005">
    <flag eulerdamp="disable"/>
  </option>

    <asset>
        <texture type="skybox" name="skybox" builtin="gradient" mark="random" rgb1="0.4 0.6 0.8" rgb2="0 0 0" markrgb="1 1 1" width="800" height="4800" />
        <texture type="2d" name="grid" builtin="checker" mark="edge" rgb1="0.1 0.2 0.3" rgb2="0.2 0.3 0.4" markrgb="0.2 0.3 0.4" width="300" height="300" />
        <material name="grid" texture="grid" texuniform="true" reflectance="0.2" />
        <material name="self" rgba="0.7 0.5 0.3 1" />
        <material name="self_default" rgba="0.7 0.5 0.3 1" />
        <material name="self_highlight" rgba="0 0.5 0.3 1" />
        <material name="effector" rgba="0.7 0.4 0.2 1" />
        <material name="effector_default" rgba="0.7 0.4 0.2 1" />
        <material name="effector_highlight" rgba="0 0.5 0.3 1" />
        <material name="decoration" rgba="0.3 0.5 0.7 1" />
        <material name="eye" rgba="0 0.2 1 1" />
        <material name="target" rgba="0.6 0.3 0.3 1" />
        <material name="target_default" rgba="0.6 0.3 0.3 1" />
        <material name="target_highlight" rgba="0.6 0.3 0.3 0.4" />
    </asset>

    <option timestep="0.01"> </option>
<!--    <default class="finger">-->
<!--        <site type="ellipsoid" size=".025 .03 .025" rgba=".5 .5 .5 .3" group="3"/>-->
<!--    </default>-->


    <worldbody>
        <geom name="ground" size="0.61 0.61 0.1" pos="-0.0 0 0.0" type="plane" rgba="0.25 0.5 1 1"/>
        <geom name="wall_x" size="0.05 0.61 0.02" pos="-0.61 0 0.05" quat="0.707107 0 0.707107 0" type="plane" rgba="0.5 0.15 0 1"/>
        <geom name="wall_y" size="0.61 0.05 0.02" pos="0 -0.61 0.05" quat="0.707107 -0.707107 0 0" type="plane" rgba="0.5 0.15 0 1"/>
        <geom name="wall_neg_x" size="0.05 0.61 0.02" pos="0.61 0 0.05" quat="0.707107 0 -0.707107 0" type="plane" rgba="0.5 0.15 0 1"/>
        <geom name="wall_neg_y" size="0.61 0.05 0.02" pos="0 0.61 0.05" quat="0.707107 0.707107 0 0" type="plane" rgba="0.5 0.15 0 1"/>
        <camera name="fixed" pos="0 0 0.75" />
        <light name="light" pos="0 0 1" dir="0 0 -1" />


        <body name ="finger" pos="0 0 0.035" quat="0.707107 0.707107 0 0">
            <!-- <geom name="proximal_decoration" type="cylinder" fromto="0 -.033 0 0 .033 0" size=".034" material="decoration" /> -->
            <joint name="proximal" range="0 6.28318530718" axis="0 -1 0" damping="0.05" limited="false" />
            <geom name="proximal" type="capsule" material="self" size=".03" fromto="0 0 0 0 0 -.17" contype="0" conaffinity="0"/>
            <body name="distal" pos="0 0 -.18">
                <joint name="distal"  range="0 6.28318530718" axis="0 -1 0" damping="0.05" limited="false"/>
                <geom name="distal" type="capsule" size=".028" material="self" fromto="0 0 0 0 0 -.16" contype="0" conaffinity="0"/>
                <body name="distal2" pos="0 0 -.18">
                    <joint name="distal2" range="0 6.28318530718" axis="0 -1 0" damping="0.05" limited="false"/>
                    <geom name="distal2" type="capsule" size=".028" material="self" fromto="0 0 0 0 0 -.16" contype="0" conaffinity="0"/>
                    <geom name="fingertip2" type="capsule" size=".03" material="effector" fromto="0 0 -.13 0 0 -.161"/>
                    <site name="touchtop2" pos=".01 0 -.17"/>
                    <site name="touchbottom2" pos="-.01 0 -.17"/>
                </body>
            </body>
        </body>

        <body name="pointmass" pos="-.0 .0 .042">
            <camera name="cam0" pos="0 -0.3 0.3" xyaxes="1 0 0 0 0.7 0.7"/>
            <joint name="root_x" type="slide"  pos="0 0 0" axis="1 0 0" damping="3" frictionloss=".01"/>
            <joint name="root_y" type="slide"  pos="0 0 0" axis="0 1 0" damping="3" frictionloss=".01"/>
            <geom name="pointmass" type="sphere" size=".042" material="self" mass=".6" condim="3"  group="2" solimp="0.05 0.7 0.001" solref="0.02 1" contype="0" conaffinity="0"/>
        </body>

        <geom name="target" pos="0.25 -0.25 0.022" material="target" type="sphere" rgba="0.5 1 0 0.25"  size=".045" contype="0" conaffinity="0"/>
    </worldbody>

    <tendon>
        <fixed name="t1">
            <joint joint="root_x" coef="1"/>
            <joint joint="root_y" coef="0"/>
        </fixed>
        <fixed name="t2">
            <joint joint="root_x" coef="0"/>
            <joint joint="root_y" coef="1"/>
        </fixed>
    </tendon>

    <actuator>
        <general name="proximal" joint="proximal" gear="0.5 0 0 0 0 0" />
        <general name="distal" joint="distal" gear="0.625 0 0 0 0 0" />
        <general name="distal2" joint="distal2" gear="0.75 0 0 0 0 0" />
    </actuator>

    <sensor>
        <framepos name="proximal_frame" objtype="body" objname="pointmass"/>
    </sensor>

    <contact>
        <exclude body1="pointmass" body2="world"/>
        <exclude body1="distal" body2="world"/>
        <exclude body1="distal2" body2="world"/>
        <exclude body1="finger" body2="world"/>
    </contact>


</mujoco>
